Workbook
Name AGOSTO: #REF!

Sheet DATOS
B2: DATOS GENERALES
B3: NOMBRE DE LA ESCUELA: | D3: EST 128
B4: NOMBRE DEL DOCENTE: | D4: Omar Mata
B5: GRADO: | D5: 3
B6: GRUPO: | D6: E
B9: ALUMNOS
B10: N° | C10: Nombre
B11: 1 | C11: ARMENDARIZ CUELLAR MIA ISABELLA
B12: 2 | C12: BLANCO SALGADO LLUVIA CRISTAL
B13: 3 | C13: CANTU AGUILAR ASHLEY DAYANA
B14: 4 | C14: CRUZ HERNÁNDEZ ALAN ABDIEL
B15: 5 | C15: DE LEON SALINAS VANESA MONSERRAT
B16: 6 | C16: DORIA GUERRA DAILY ALESSANDRA
B17: 7 | C17: ELIZONDO ROMERO MONTSERRAT GUADALUPE
B18: 8 | C18: GARCIA PINEDA IKER ALEJANDRO
B19: 9 | C19: GONZÁLEZ HERNÁNDEZ LUIS Á_x0081_NGEL
B20: 10 | C20: GRIMALDO PUENTE SAMANTHA SARAHI
B21: 11 | C21: GUERRERO RODRIGUEZ KEYSHA CECILIA
B22: 12 | C22: HERNANDEZ CRUZ VIRIDIANA MARIE
... B40: 30 | C40: RAMÍREZ CORREA ALISSON
B41: 31
B42: 32
B43: 33
B44: 34
B45: 35
B46: 36
B47: 37
B48: 38
B49: 39
B50: 40
B51: 41
B52: 42
... B55: 45

Sheet 1er Trimestre
A1: =DATOS!D3 -> EST 128 | BV1: ACTIVIDADES | BX1: 0.2
A2: DOCENTE: | B2: =DATOS!D4 -> Omar Mata | BV2: TAREAS | BX2: 0.2
A3: GRADO: | B3: =DATOS!D5 -> 3 | C3: =DATOS!D6 -> E | BO3: PROYECTOS | BV3: PROYECTOS | BX3: 0.2
A4: Materia | B4: TECNOLOGÍA | BO4: Calaveritas prehispánicas y aserrín pintado | BV4: PARTICIPACIÓN | BX4: 0.1
BV5: CONDUCTA | BX5: 0.1
BV6: EVALUACIÓN | BX6: 0.2
BV7: PORCENTAJE TOTAL | BX7: =SUM(BX1:BX6) -> 1
D9: ACTIVIDADES | AJ9: TAREAS | BU9: PARTICIPACIÓN | BV9: CONDUCTA | BW9: EVALUACIÓN (Examen) | BX9: CALIF FINAL
A10: N° | B10: NOMBRE | D10: 1 | E10: 2 | F10: 3 | G10: 4 | H10: 5 | I10: 6 | J10: 7 | K10: 8 | L10: 9 | M10: 10 | N10: 11 | O10: 12 | P10: 13 | Q10: 14 | R10: 15 | S10: 16 | T10: 17 | U10: 18 | V10: 19 | W10: 20 | X10: 21 | Y10: 21 | Z10: 22 | AA10: 23 | AB10: 24 | AC10: 25 | AD10: 26 | AE10: 27 | AF10: 28 | AG10: 29 | AH10: 30 | AI10: PROMEDIO ACTIVIDADES | AJ10: 1 | AK10: 2 | AL10: 3 | AM10: 4 | AN10: 5 | AO10: 6 | AP10: 7 | AQ10: 8 | AR10: 9 | AS10: 10 | AT10: 11 | AU10: 12 | AV10: 13 | AW10: 14 | AX10: 15 | AY10: 16 | AZ10: 17 | BA10: 18 | BB10: 19 | BC10: 20 | BD10: 21 | BE10: 22 | BF10: 23 | BG10: 24 | BH10: 25 | BI10: 26 | BJ10: 27 | BK10: 28 | BL10: 29 | BM10: 30 | BN10: PROMEDIO TAREAS | BO10: 1 | BP10: 2 | BQ10: 3 | BR10: 4 | BS10: 5 | BT10: PROMEDIO PROYECTOS
A11: 1 | B11: =DATOS!C11 -> ARMENDARIZ CUELLAR MIA ISABELLA | D11: 10 | E11: 10 | F11: 10 | G11: 10 | H11: 9 | I11: 9 | J11: 9 | K11: 10 | L11: 10 | M11: 9 | N11: 9 | O11: 9 | P11: 9 | Q11: 9 | R11: 9 | S11: 9 | T11: 10 | U11: 10 | V11: 10 | W11: 9 | X11: 10 | AI11: =AVERAGE(D11:AH11) -> 9.4761905 | AJ11: 9 | AK11: 9 | AL11: 9 | AM11: 9 | AN11: 9 | BN11: =AVERAGE(AJ11:BM11) -> 9 | BO11: 10 | BT11: =AVERAGE(BO11:BS11) -> 10 | BU11: 9 | BV11: 9 | BW11: 7.5 | BX11: =(AI11*$BX$1)+(BN11*$BX$2)+(BT11*$BX$3)+(BU11*$BX$4)+(BV11*$BX$5)+(BW11*$BX$6) -> 8.9952381
A12: 2 | B12: =DATOS!C12 -> BLANCO SALGADO LLUVIA CRISTAL | D12: 9 | E12: 9 | F12: 9 | G12: 9 | H12: 9 | I12: 9 | J12: 9 | K12: 9 | L12: 9 | M12: 9 | N12: 9 | O12: 9 | P12: 9 | Q12: 9 | R12: 9 | S12: 9 | T12: 9 | U12: 9 | V12: 9 | W12: 9 | X12: 9 | AI12: =AVERAGE(D12:AH12) -> 9 | AJ12: 7 | AK12: 6 | AL12: 7 | AM12: 8 | AN12: 8 | BN12: =AVERAGE(AJ12:BM12) -> 7.2 | BO12: 9 | BT12: =AVERAGE(BO12:BS12) -> 9 | BU12: 7 | BV12: 8 | BW12: 5.5 | BX12: =(AI12*$BX$1)+(BN12*$BX$2)+(BT12*$BX$3)+(BU12*$BX$4)+(BV12*$BX$5)+(BW12*$BX$6) -> 7.64
A13: 3 | B13: =DATOS!C13 -> CANTU AGUILAR ASHLEY DAYANA | D13: 7 | E13: 7 | F13: 7 | G13: 7 | H13: 7 | I13: 7 | J13: 7 | K13: 7 | L13: 7 | M13: 7 | N13: 7 | O13: 7 | P13: 7 | Q13: 7 | R13: 7 | S13: 7 | T13: 7 | U13: 7 | V13: 7 | W13: 7 | X13: 7 | AI13: =AVERAGE(D13:AH13) -> 7 | AJ13: 7 | AK13: 6 | AL13: 7 | AM13: 7 | AN13: 7 | BN13: =AVERAGE(AJ13:BM13) -> 6.8 | BO13: 9 | BT13: =AVERAGE(BO13:BS13) -> 9 | BU13: 6 | BV13: 7 | BW13: 6.5 | BX13: =(AI13*$BX$1)+(BN13*$BX$2)+(BT13*$BX$3)+(BU13*$BX$4)+(BV13*$BX$5)+(BW13*$BX$6) -> 7.16
A14: 4 | B14: =DATOS!C14 -> CRUZ HERNÁNDEZ ALAN ABDIEL | D14: 10 | E14: 9 | F14: 9 | G14: 9 | H14: 10 | I14: 9 | J14: 9 | K14: 9 | L14: 9 | M14: 9 | N14: 7 | O14: 9 | P14: 9 | Q14: 8 | R14: 8 | S14: 9 | T14: 9 | U14: 10 | V14: 9 | W14: 9 | X14: 9 | AI14: =AVERAGE(D14:AH14) -> 8.952381 | AJ14: 8 | AK14: 8 | AL14: 7 | AM14: 7 | AN14: 8 | BN14: =AVERAGE(AJ14:BM14) -> 7.6 | BO14: 10 | BT14: =AVERAGE(BO14:BS14) -> 10 | BU14: 7 | BV14: 8 | BW14: 4.5 | BX14: =(AI14*$BX$1)+(BN14*$BX$2)+(BT14*$BX$3)+(BU14*$BX$4)+(BV14*$BX$5)+(BW14*$BX$6) -> 7.7104762
A15: 5 | B15: =DATOS!C15 -> DE LEON SALINAS VANESA MONSERRAT | D15: 10 | E15: 10 | F15: 10 | G15: 10 | H15: 10 | I15: 8 | J15: 8 | K15: 9 | L15: 9 | M15: 9 | N15: 8 | O15: 9 | P15: 9 | Q15: 9 | R15: 9 | S15: 9 | T15: 10 | U15: 10 | V15: 9 | W15: 8 | X15: 8 | AI15: =AVERAGE(D15:AH15) -> 9.0952381 | AJ15: 10 | AK15: 10 | AL15: 10 | AM15: 10 | AN15: 10 | BN15: =AVERAGE(AJ15:BM15) -> 10 | BO15: 9 | BT15: =AVERAGE(BO15:BS15) -> 9 | BU15: 7 | BV15: 9 | BW15: 4.5 | BX15: =(AI15*$BX$1)+(BN15*$BX$2)+(BT15*$BX$3)+(BU15*$BX$4)+(BV15*$BX$5)+(BW15*$BX$6) -> 8.1190476
A16: 6 | B16: =DATOS!C16 -> DORIA GUERRA DAILY ALESSANDRA | D16: 10 | E16: 10 | F16: 10 | G16: 10 | H16: 10 | I16: 10 | J16: 9 | K16: 9 | L16: 9 | M16: 9 | N16: 9 | O16: 9 | P16: 9 | Q16: 9 | R16: 9 | S16: 10 | T16: 10 | U16: 10 | V16: 10 | W16: 10 | X16: 9 | AI16: =AVERAGE(D16:AH16) -> 9.5238095 | AJ16: 10 | AK16: 10 | AL16: 10 | AM16: 10 | AN16: 9 | BN16: =AVERAGE(AJ16:BM16) -> 9.8 | BO16: 10 | BT16: =AVERAGE(BO16:BS16) -> 10 | BU16: 10 | BV16: 9 | BW16: 7 | BX16: =(AI16*$BX$1)+(BN16*$BX$2)+(BT16*$BX$3)+(BU16*$BX$4)+(BV16*$BX$5)+(BW16*$BX$6) -> 9.1647619
A17: 7 | B17: =DATOS!C17 -> ELIZONDO ROMERO MONTSERRAT GUADALUPE | D17: 10 | E17: 10 | F17: 10 | G17: 10 | H17: 10 | I17: 10 | J17: 9 | K17: 9 | L17: 9 | M17: 9 | N17: 9.5 | O17: 9 | P17: 9 | Q17: 9 | R17: 9 | S17: 9 | T17: 9 | U17: 9 | V17: 10 | W17: 10 | X17: 10 | AI17: =AVERAGE(D17:AH17) -> 9.452381 | AJ17: 9 | AK17: 9 | AL17: 9 | AM17: 9 | AN17: 9 | BN17: =AVERAGE(AJ17:BM17) -> 9 | BO17: 10 | BT17: =AVERAGE(BO17:BS17) -> 10 | BU17: 9 | BV17: 9 | BW17: 6.5 | BX17: =(AI17*$BX$1)+(BN17*$BX$2)+(BT17*$BX$3)+(BU17*$BX$4)+(BV17*$BX$5)+(BW17*$BX$6) -> 8.7904762
A18: 8 | B18: =DATOS!C18 -> GARCIA PINEDA IKER ALEJANDRO | D18: 10 | E18: 10 | F18: 10 | G18: 8 | H18: 8 | I18: 8 | J18: 8 | K18: 10 | L18: 8 | M18: 9 | N18: 9 | O18: 8 | P18: 8 | Q18: 8 | R18: 10 | S18: 9 | T18: 9 | U18: 9 | V18: 9 | W18: 9 | X18: 9 | AI18: =AVERAGE(D18:AH18) -> 8.8571429 | AJ18: 10 | AK18: 9 | AL18: 9 | AM18: 8 | AN18: 8 | BN18: =AVERAGE(AJ18:BM18) -> 8.8 | BO18: 9 | BT18: =AVERAGE(BO18:BS18) -> 9 | BU18: 8 | BV18: 9 | BW18: 5.5 | BX18: =(AI18*$BX$1)+(BN18*$BX$2)+(BT18*$BX$3)+(BU18*$BX$4)+(BV18*$BX$5)+(BW18*$BX$6) -> 8.1314286
A19: 9 | B19: =DATOS!C19 -> GONZÁLEZ HERNÁNDEZ LUIS Á_x0081_NGEL | D19: 9 | E19: 9 | F19: 9 | G19: 9 | H19: 9 | I19: 9 | J19: 9 | K19: 9 | L19: 9 | M19: 9 | N19: 9 | O19: 9 | P19: 9 | Q19: 9 | R19: 9 | S19: 9 | T19: 9 | U19: 9 | V19: 9 | W19: 9 | X19: 9 | AI19: =AVERAGE(D19:AH19) -> 9 | AJ19: 8 | AK19: 8 | AL19: 8 | AM19: 8 | AN19: 9 | BN19: =AVERAGE(AJ19:BM19) -> 8.2 | BO19: 10 | BT19: =AVERAGE(BO19:BS19) -> 10 | BU19: 7 | BV19: 7 | BW19: 4 | BX19: =(AI19*$BX$1)+(BN19*$BX$2)+(BT19*$BX$3)+(BU19*$BX$4)+(BV19*$BX$5)+(BW19*$BX$6) -> 7.64
A20: 10 | B20: =DATOS!C20 -> GRIMALDO PUENTE SAMANTHA SARAHI | D20: 10 | E20: 10 | F20: 10 | G20: 9 | H20: 10 | I20: 10 | J20: 9 | K20: 9 | L20: 9 | M20: 10 | N20: 10 | O20: 9 | P20: 9 | Q20: 9 | R20: 9 | S20: 9 | T20: 9 | U20: 10 | V20: 10 | W20: 10 | X20: 9 | AI20: =AVERAGE(D20:AH20) -> 9.4761905 | AJ20: 9 | AK20: 9 | AL20: 9 | AM20: 9 | AN20: 9 | BN20: =AVERAGE(AJ20:BM20) -> 9 | BO20: 10 | BT20: =AVERAGE(BO20:BS20) -> 10 | BU20: 9 | BV20: 9 | BW20: 7.5 | BX20: =(AI20*$BX$1)+(BN20*$BX$2)+(BT20*$BX$3)+(BU20*$BX$4)+(BV20*$BX$5)+(BW20*$BX$6) -> 8.9952381
A21: 11 | B21: =DATOS!C21 -> GUERRERO RODRIGUEZ KEYSHA CECILIA | D21: 5 | E21: 5 | F21: 5 | G21: 5 | H21: 5 | I21: 5 | J21: 5 | K21: 5 | L21: 5 | M21: 5 | N21: 5 | O21: 5 | P21: 5 | Q21: 5 | R21: 5 | S21: 5 | T21: 6 | U21: 6 | V21: 6 | W21: 6 | X21: 6 | AI21: =AVERAGE(D21:AH21) -> 5.2380952 | AJ21: 6 | AK21: 6 | AL21: 6 | AM21: 6 | AN21: 6 | BN21: =AVERAGE(AJ21:BM21) -> 6 | BO21: 7 | BT21: =AVERAGE(BO21:BS21) -> 7 | BU21: 6 | BV21: 7 | BW21: 3.5 | BX21: =(AI21*$BX$1)+(BN21*$BX$2)+(BT21*$BX$3)+(BU21*$BX$4)+(BV21*$BX$5)+(BW21*$BX$6) -> 5.647619
A22: 12 | B22: =DATOS!C22 -> HERNANDEZ CRUZ VIRIDIANA MARIE | D22: 10 | E22: 10 | F22: 10 | G22: 10 | H22: 10 | I22: 10 | J22: 10 | K22: 10 | L22: 10 | M22: 10 | N22: 10 | O22: 10 | P22: 10 | Q22: 10 | R22: 10 | S22: 10 | T22: 10 | U22: 10 | V22: 10 | W22: 10 | X22: 10 | AI22: =AVERAGE(D22:AH22) -> 10 | AJ22: 10 | AK22: 9 | AL22: 9 | AM22: 9 | AN22: 9 | BN22: =AVERAGE(AJ22:BM22) -> 9.2 | BO22: 10 | BT22: =AVERAGE(BO22:BS22) -> 10 | BU22: 7 | BV22: 9 | BW22: 4.5 | BX22: =(AI22*$BX$1)+(BN22*$BX$2)+(BT22*$BX$3)+(BU22*$BX$4)+(BV22*$BX$5)+(BW22*$BX$6) -> 8.34
... A27: 17 | B27: =DATOS!C27 -> MEZA TURRUBIATES BRITANY YAHIRALIZ | D27: 10 | E27: 10 | F27: 10 | G27: 10 | H27: 10 | I27: 10 | J27: 10 | K27: 10 | L27: 10 | M27: 10 | N27: 10 | O27: 10 | P27: 10 | Q27: 10 | R27: 10 | S27: 10 | T27: 10 | U27: 10 | V27: 10 | W27: 10 | X27: 10 | AI27: =AVERAGE(D27:AH27) -> 10 | AJ27: 8 | AK27: 8 | AL27: 8 | AM27: 8 | AN27: 8 | BN27: =AVERAGE(AJ27:BM27) -> 8 | BO27: 9 | BT27: =AVERAGE(BO27:BS27) -> 9 | BU27: 9 | BV27: 9 | BW27: 5 | BX27: =(AI27*$BX$1)+(BN27*$BX$2)+(BT27*$BX$3)+(BU27*$BX$4)+(BV27*$BX$5)+(BW27*$BX$6) -> 8.2
A28: 18 | B28: =DATOS!C28 -> PEÑA MEDELLÍN CORAL ANJURY | D28: 10 | E28: 10 | F28: 10 | G28: 10 | H28: 10 | I28: 10 | J28: 10 | K28: 10 | L28: 10 | M28: 10 | N28: 10 | O28: 10 | P28: 10 | Q28: 10 | R28: 10 | S28: 10 | T28: 10 | U28: 10 | V28: 10 | W28: 10 | X28: 10 | AI28: =AVERAGE(D28:AH28) -> 10 | AJ28: 10 | AK28: 10 | AL28: 10 | AM28: 10 | AN28: 10 | BN28: =AVERAGE(AJ28:BM28) -> 10 | BO28: 10 | BT28: 10 | BU28: 9 | BV28: 8 | BX28: =(AI28*$BX$1)+(BN28*$BX$2)+(BT28*$BX$3)+(BU28*$BX$4)+(BV28*$BX$5)+(BW28*$BX$6) -> 7.7
A29: 19 | B29: =DATOS!C29 -> RAMIREZ GUEIXPAL VANIA GUADALUPE | D29: 10 | E29: 10 | F29: 10 | G29: 10 | H29: 10 | I29: 10 | J29: 10 | K29: 10 | L29: 10 | M29: 10 | N29: 10 | O29: 10 | P29: 10 | Q29: 10 | R29: 10 | S29: 10 | T29: 10 | U29: 10 | V29: 10 | W29: 10 | X29: 10 | AI29: =AVERAGE(D29:AH29) -> 10 | AJ29: 10 | AK29: 10 | AL29: 10 | AM29: 10 | AN29: 10 | BN29: =AVERAGE(AJ29:BM29) -> 10 | BO29: 10 | BT29: =AVERAGE(BO29:BS29) -> 10 | BU29: 8 | BV29: 9 | BW29: 7 | BX29: =(AI29*$BX$1)+(BN29*$BX$2)+(BT29*$BX$3)+(BU29*$BX$4)+(BV29*$BX$5)+(BW29*$BX$6) -> 9.1
A30: 20 | B30: =DATOS!C30 -> RAMIREZ MARTINEZ EDWIN EMMANUEL | D30: 7 | E30: 7 | F30: 7 | G30: 8 | H30: 8 | I30: 8 | J30: 8 | K30: 7 | L30: 9 | M30: 7 | N30: 7 | O30: 7 | P30: 6 | Q30: 6 | R30: 6 | S30: 6 | T30: 6 | U30: 7 | V30: 7 | W30: 7 | X30: 7 | AI30: =AVERAGE(D30:AH30) -> 7.047619 | AJ30: 10 | AK30: 10 | AL30: 10 | AM30: 10 | AN30: 10 | BN30: =AVERAGE(AJ30:BM30) -> 10 | BO30: 10 | BT30: =AVERAGE(BO30:BS30) -> 10 | BU30: 10 | BV30: 8 | BW30: 4.7 | BX30: =(AI30*$BX$1)+(BN30*$BX$2)+(BT30*$BX$3)+(BU30*$BX$4)+(BV30*$BX$5)+(BW30*$BX$6) -> 8.1495238
A31: 21 | B31: =DATOS!C31 -> RANGEL GARCÍA DANIEL TIMOTEO | D31: 9 | E31: 9 | F31: 9 | G31: 9 | H31: 9 | I31: 9 | J31: 9 | K31: 9 | L31: 9 | M31: 9 | N31: 9 | O31: 9 | P31: 9 | Q31: 9 | R31: 9 | S31: 9 | T31: 9 | U31: 9 | V31: 9 | W31: 9 | X31: 9 | AI31: =AVERAGE(D31:AH31) -> 9 | AJ31: 10 | AK31: 7 | AL31: 7 | AM31: 7 | AN31: 7 | BN31: =AVERAGE(AJ31:BM31) -> 7.6 | BO31: 9 | BT31: =AVERAGE(BO31:BS31) -> 9 | BU31: 7 | BV31: 6 | BW31: 5.5 | BX31: =(AI31*$BX$1)+(BN31*$BX$2)+(BT31*$BX$3)+(BU31*$BX$4)+(BV31*$BX$5)+(BW31*$BX$6) -> 7.52
A32: 22 | B32: =DATOS!C32 -> ROCHA RAMÍREZ CRISTIAN GUADALUPE | D32: 5 | E32: 5 | F32: 5 | G32: 5 | H32: 5 | I32: 5 | J32: 5 | K32: 5 | L32: 5 | M32: 5 | N32: 5 | O32: 5 | P32: 5 | Q32: 5 | R32: 5 | S32: 5 | T32: 5 | U32: 5 | V32: 5 | W32: 5 | X32: 5 | AI32: =AVERAGE(D32:AH32) -> 5 | AJ32: 5 | AK32: 5 | AL32: 5 | AM32: 5 | AN32: 5 | BN32: =AVERAGE(AJ32:BM32) -> 5 | BO32: 9 | BT32: =AVERAGE(BO32:BS32) -> 9 | BU32: 9 | BV32: 7 | BW32: 2.5 | BX32: =(AI32*$BX$1)+(BN32*$BX$2)+(BT32*$BX$3)+(BU32*$BX$4)+(BV32*$BX$5)+(BW32*$BX$6) -> 5.9
A33: 23 | B33: =DATOS!C33 -> RODULFO ARGÜELLO ISAÍAS TADEO | D33: 7 | E33: 9 | F33: 8 | G33: 8 | H33: 8 | I33: 8 | J33: 8 | K33: 8 | L33: 8 | M33: 8 | N33: 8 | O33: 8 | P33: 8 | Q33: 8 | R33: 9 | S33: 9 | T33: 8 | U33: 8 | V33: 7 | W33: 7 | X33: 9 | AI33: =AVERAGE(D33:AH33) -> 8.047619 | AJ33: 10 | AK33: 10 | AL33: 8 | AM33: 8 | AN33: 8 | BN33: =AVERAGE(AJ33:BM33) -> 8.8 | BO33: 9 | BT33: =AVERAGE(BO33:BS33) -> 9 | BU33: 9 | BV33: 8 | BW33: 5 | BX33: =(AI33*$BX$1)+(BN33*$BX$2)+(BT33*$BX$3)+(BU33*$BX$4)+(BV33*$BX$5)+(BW33*$BX$6) -> 7.8695238
A34: 24 | B34: =DATOS!C34 -> RUBIO HERNÁNDEZ EVELIN | D34: 10 | E34: 10 | F34: 10 | G34: 10 | H34: 10 | I34: 10 | J34: 10 | K34: 10 | L34: 10 | M34: 10 | N34: 10 | O34: 10 | P34: 10 | Q34: 10 | R34: 10 | S34: 10 | T34: 10 | U34: 10 | V34: 10 | W34: 10 | X34: 10 | AI34: =AVERAGE(D34:AH34) -> 10 | AJ34: 10 | AK34: 10 | AL34: 10 | AM34: 10 | AN34: 8 | BN34: =AVERAGE(AJ34:BM34) -> 9.6 | BO34: 10 | BT34: =AVERAGE(BO34:BS34) -> 10 | BU34: 10 | BV34: 8 | BW34: 7 | BX34: =(AI34*$BX$1)+(BN34*$BX$2)+(BT34*$BX$3)+(BU34*$BX$4)+(BV34*$BX$5)+(BW34*$BX$6) -> 9.12
A35: 25 | B35: =DATOS!C35 -> SALAZAR GOMEZ OSVALDO DAMIAN | D35: 10 | E35: 10 | F35: 7 | G35: 7 | H35: 7 | I35: 8 | J35: 8 | K35: 7 | L35: 7 | M35: 7 | N35: 7 | O35: 7 | P35: 7 | Q35: 7 | R35: 6 | S35: 6 | T35: 6 | U35: 6 | V35: 7 | W35: 6 | X35: 6 | AI35: =AVERAGE(D35:AH35) -> 7.0952381 | AJ35: 10 | AK35: 10 | AL35: 10 | AM35: 10 | AN35: 10 | BN35: =AVERAGE(AJ35:BM35) -> 10 | BO35: 9 | BT35: =AVERAGE(BO35:BS35) -> 9 | BU35: 10 | BV35: 9 | BW35: 5.5 | BX35: =(AI35*$BX$1)+(BN35*$BX$2)+(BT35*$BX$3)+(BU35*$BX$4)+(BV35*$BX$5)+(BW35*$BX$6) -> 8.2190476
A36: 26 | B36: =DATOS!C36 -> SANTIAGO DEL ANGEL JESUS ANTONIO | D36: 9 | E36: 9 | F36: 9 | G36: 8 | H36: 8 | I36: 8 | J36: 8 | K36: 8 | L36: 8 | M36: 8 | N36: 9 | O36: 7 | P36: 9 | Q36: 9 | R36: 8 | S36: 8 | T36: 8 | U36: 8 | V36: 9 | W36: 9 | X36: 9 | AI36: =AVERAGE(D36:AH36) -> 8.3809524 | AJ36: 8 | AK36: 8 | AL36: 9 | AM36: 9 | AN36: 9 | BN36: =AVERAGE(AJ36:BM36) -> 8.6 | BO36: 10 | BT36: =AVERAGE(BO36:BS36) -> 10 | BU36: 9 | BV36: 7 | BW36: 7.5 | BX36: =(AI36*$BX$1)+(BN36*$BX$2)+(BT36*$BX$3)+(BU36*$BX$4)+(BV36*$BX$5)+(BW36*$BX$6) -> 8.4961905
A37: 27 | B37: =DATOS!C37 -> SILVA GONZALEZ LEONARDO SAID | D37: 8 | E37: 8 | F37: 7 | G37: 7 | H37: 8 | I37: 7 | J37: 8 | K37: 9 | L37: 9 | M37: 9 | N37: 8 | O37: 8 | P37: 8 | Q37: 8 | R37: 7 | S37: 8 | T37: 8 | U37: 9 | V37: 8 | W37: 8 | X37: 8 | AI37: =AVERAGE(D37:AH37) -> 8 | AJ37: 10 | AK37: 10 | AL37: 6 | AM37: 7 | AN37: 7 | BN37: =AVERAGE(AJ37:BM37) -> 8 | BO37: 8 | BT37: =AVERAGE(BO37:BS37) -> 8 | BU37: 9 | BV37: 7 | BW37: 5.5 | BX37: =(AI37*$BX$1)+(BN37*$BX$2)+(BT37*$BX$3)+(BU37*$BX$4)+(BV37*$BX$5)+(BW37*$BX$6) -> 7.5
A38: 28 | B38: =DATOS!C38 -> TOBIAS LOZANO ESTEFANY LIZBETH | D38: 9 | E38: 9 | F38: 9 | G38: 9 | H38: 9 | I38: 9 | J38: 9 | K38: 9 | L38: 9 | M38: 9 | N38: 9 | O38: 9 | P38: 9 | Q38: 9 | R38: 9 | S38: 9 | T38: 9 | U38: 9 | V38: 9 | W38: 9 | X38: 9 | AI38: =AVERAGE(D38:AH38) -> 9 | AJ38: 7 | AK38: 7 | AL38: 7 | AM38: 7 | AN38: 7 | BN38: =AVERAGE(AJ38:BM38) -> 7 | BO38: 10 | BT38: =AVERAGE(BO38:BS38) -> 10 | BU38: 7 | BV38: 7 | BW38: 5.5 | BX38: =(AI38*$BX$1)+(BN38*$BX$2)+(BT38*$BX$3)+(BU38*$BX$4)+(BV38*$BX$5)+(BW38*$BX$6) -> 7.7
A39: 29 | B39: =DATOS!C39 -> TORRES MEDINA JOSHLEY ALEJANDRO | D39: 5 | E39: 5 | F39: 5 | G39: 5 | H39: 5 | I39: 5 | J39: 5 | K39: 5 | L39: 5 | M39: 5 | N39: 6 | O39: 5 | P39: 5 | Q39: 5 | R39: 5 | S39: 5 | T39: 5 | U39: 5 | V39: 5 | W39: 5 | X39: 5 | AI39: =AVERAGE(D39:AH39) -> 5.047619 | AJ39: 5 | AK39: 5 | AL39: 5 | AM39: 5 | AN39: 5 | BN39: =AVERAGE(AJ39:BM39) -> 5 | BO39: 7 | BT39: =AVERAGE(BO39:BS39) -> 7 | BU39: 7 | BV39: 7 | BW39: 5.5 | BX39: =(AI39*$BX$1)+(BN39*$BX$2)+(BT39*$BX$3)+(BU39*$BX$4)+(BV39*$BX$5)+(BW39*$BX$6) -> 5.9095238
A40: 30 | B40: =DATOS!C40 -> RAMÍREZ CORREA ALISSON
A41: 31 | B41: =DATOS!C41
A42: 32 | B42: =DATOS!C42
A43: 33 | B43: =DATOS!C43
A44: 34 | B44: =DATOS!C44
A45: 35 | B45: =DATOS!C45
...

Sheet 2do Trimestre
A1: =DATOS!D3 -> EST 128 | BW1: ACTIVIDADES | BY1: 0.2
A2: DOCENTE: | B2: =DATOS!D4 -> Omar Mata | BW2: TAREAS | BY2: 0.2
A3: GRADO: | B3: =DATOS!D5 -> 3 | C3: =DATOS!D6 -> E | BN3: PROYECTOS | BW3: PROYECTOS | BY3: 0.2
A4: Materia | B4: TECNOLOGÍA | BN4: Mesa de Postres | BO4: Emprendimiento | BP4: Rally | BW4: PARTICIPACIÓN | BY4: 0.1
BW5: CONDUCTA | BY5: 0.1
BW6: EVALUACIÓN | BY6: 0.2
BW7: PORCENTAJE TOTAL | BY7: =SUM(BY1:BY6) -> 1
D9: ACTIVIDADES | AI9: TAREAS | BV9: PARTICIPACIÓN | BW9: CONDUCTA | BX9: EVALUACIÓN (Examen) | BY9: CALIF FINAL
A10: N° | B10: NOMBRE | D10: 1 | E10: 2 | F10: 3 | G10: 4 | H10: 5 | I10: 6 | J10: 7 | K10: 8 | L10: 9 | M10: 10 | N10: 11 | O10: 12 | P10: 13 | Q10: 14 | R10: 15 | S10: 16 | T10: 17 | U10: 18 | V10: 19 | W10: 20 | X10: 21 | Y10: 22 | Z10: 23 | AA10: 24 | AB10: 25 | AC10: 26 | AD10: 27 | AE10: 28 | AF10: 29 | AG10: 30 | AH10: PROMEDIO ACTIVIDADES | AI10: 1 | AJ10: 2 | AK10: 3 | AL10: 4 | AM10: 5 | AN10: 6 | AO10: 7 | AP10: 8 | AQ10: 9 | AR10: 10 | AS10: 11 | AT10: 12 | AU10: 13 | AV10: 14 | AW10: 15 | AX10: 16 | AY10: 17 | AZ10: 18 | BA10: 19 | BB10: 20 | BC10: 21 | BD10: 22 | BE10: 23 | BF10: 24 | BG10: 25 | BH10: 26 | BI10: 27 | BJ10: 28 | BK10: 29 | BL10: 30 | BM10: PROMEDIO TAREAS | BN10: 1 | BO10: 2 | BP10: 3 | BQ10: 2 | BR10: 3 | BS10: 4 | BT10: 5 | BU10: PROMEDIO PROYECTOS
A11: 1 | B11: =DATOS!C11 -> ARMENDARIZ CUELLAR MIA ISABELLA | D11: 10 | E11: 10 | F11: 10 | G11: 10 | H11: 10 | I11: 10 | J11: 10 | K11: 10 | L11: 10 | M11: 10 | N11: 10 | O11: 10 | P11: 10 | Q11: 10 | R11: 10 | S11: 10 | T11: 10 | U11: 10 | V11: 10 | W11: 10 | AH11: =AVERAGE(D11:AG11) -> 10 | AI11: 9 | BM11: =AVERAGE(AI11:BL11) -> 9 | BN11: 9 | BO11: 10 | BP11: 10 | BU11: =AVERAGE(BN11:BT11) -> 9.6666667 | BV11: 10 | BW11: 10 | BX11: 9.5 | BY11: =(AH11*$BY$1)+(BM11*$BY$2)+(BU11*$BY$3)+(BV11*$BY$4)+(BW11*$BY$5)+(BX11*$BY$6) -> 9.6333333
A12: 2 | B12: =DATOS!C12 -> BLANCO SALGADO LLUVIA CRISTAL | D12: 10 | E12: 10 | F12: 10 | G12: 10 | H12: 10 | I12: 10 | J12: 10 | K12: 10 | L12: 10 | M12: 10 | N12: 10 | O12: 10 | P12: 10 | Q12: 10 | R12: 10 | S12: 10 | T12: 10 | U12: 10 | V12: 10 | W12: 10 | AH12: =AVERAGE(D12:AG12) -> 10 | AI12: 8 | BM12: =AVERAGE(AI12:BL12) -> 8 | BN12: 9 | BO12: 10 | BP12: 10 | BU12: =AVERAGE(BN12:BT12) -> 9.6666667 | BV12: 10 | BW12: 10 | BX12: 10 | BY12: =(AH12*$BY$1)+(BM12*$BY$2)+(BU12*$BY$3)+(BV12*$BY$4)+(BW12*$BY$5)+(BX12*$BY$6) -> 9.5333333
A13: 3 | B13: =DATOS!C13 -> CANTU AGUILAR ASHLEY DAYANA | D13: 9 | E13: 7 | F13: 7 | G13: 7 | H13: 6 | I13: 6 | J13: 6 | K13: 6 | L13: 6 | M13: 6 | N13: 7 | O13: 7 | P13: 7 | Q13: 7 | R13: 6 | S13: 8 | T13: 9 | U13: 8 | V13: 7 | W13: 7 | AH13: =AVERAGE(D13:AG13) -> 6.95 | AI13: 7 | BM13: =AVERAGE(AI13:BL13) -> 7 | BN13: 8 | BO13: 9 | BP13: 10 | BU13: =AVERAGE(BN13:BT13) -> 9 | BV13: 8 | BW13: 8 | BX13: 5.5 | BY13: =(AH13*$BY$1)+(BM13*$BY$2)+(BU13*$BY$3)+(BV13*$BY$4)+(BW13*$BY$5)+(BX13*$BY$6) -> 7.29
A14: 4 | B14: =DATOS!C14 -> CRUZ HERNÁNDEZ ALAN ABDIEL | D14: 10 | E14: 9 | F14: 9 | G14: 9 | H14: 9 | I14: 9 | J14: 7 | K14: 7 | L14: 7 | M14: 8 | N14: 9 | O14: 9 | P14: 9 | Q14: 9 | R14: 10 | S14: 10 | T14: 7 | U14: 7 | V14: 7 | W14: 8 | AH14: =AVERAGE(D14:AG14) -> 8.45 | AI14: 8 | BM14: =AVERAGE(AI14:BL14) -> 8 | BN14: 8 | BO14: 9 | BP14: 10 | BU14: =AVERAGE(BN14:BT14) -> 9 | BV14: 8 | BW14: 8 | BX14: 8.5 | BY14: =(AH14*$BY$1)+(BM14*$BY$2)+(BU14*$BY$3)+(BV14*$BY$4)+(BW14*$BY$5)+(BX14*$BY$6) -> 8.39
A15: 5 | B15: =DATOS!C15 -> DE LEON SALINAS VANESA MONSERRAT | D15: 10 | E15: 10 | F15: 10 | G15: 9 | H15: 8 | I15: 9 | J15: 9 | K15: 9 | L15: 7 | M15: 7 | N15: 7 | O15: 7 | P15: 7 | Q15: 7 | R15: 9 | S15: 9 | T15: 9 | U15: 9 | V15: 9 | W15: 9 | AH15: =AVERAGE(D15:AG15) -> 8.5 | AI15: 10 | BM15: =AVERAGE(AI15:BL15) -> 10 | BN15: 8 | BO15: 9 | BP15: 10 | BU15: =AVERAGE(BN15:BT15) -> 9 | BV15: 9 | BW15: 9 | BX15: 5.5 | BY15: =(AH15*$BY$1)+(BM15*$BY$2)+(BU15*$BY$3)+(BV15*$BY$4)+(BW15*$BY$5)+(BX15*$BY$6) -> 8.4
A16: 6 | B16: =DATOS!C16 -> DORIA GUERRA DAILY ALESSANDRA | D16: 10 | E16: 10 | F16: 10 | G16: 10 | H16: 10 | I16: 10 | J16: 10 | K16: 10 | L16: 10 | M16: 10 | N16: 10 | O16: 10 | P16: 10 | Q16: 10 | R16: 10 | S16: 10 | T16: 10 | U16: 10 | V16: 10 | W16: 10 | AH16: =AVERAGE(D16:AG16) -> 10 | AI16: 10 | BM16: =AVERAGE(AI16:BL16) -> 10 | BN16: 9 | BO16: 10 | BP16: 10 | BU16: =AVERAGE(BN16:BT16) -> 9.6666667 | BV16: 10 | BW16: 10 | BX16: 9.5 | BY16: =(AH16*$BY$1)+(BM16*$BY$2)+(BU16*$BY$3)+(BV16*$BY$4)+(BW16*$BY$5)+(BX16*$BY$6) -> 9.8333333
A17: 7 | B17: =DATOS!C17 -> ELIZONDO ROMERO MONTSERRAT GUADALUPE | D17: 10 | E17: 10 | F17: 10 | G17: 8 | H17: 9 | I17: 9 | J17: 9 | K17: 7 | L17: 9 | M17: 10 | N17: 8 | O17: 10 | P17: 10 | Q17: 7 | R17: 9 | S17: 9 | T17: 9 | U17: 9 | V17: 10 | W17: 8 | AH17: =AVERAGE(D17:AG17) -> 9 | AI17: 9 | BM17: =AVERAGE(AI17:BL17) -> 9 | BN17: 8 | BO17: 9 | BP17: 10 | BU17: =AVERAGE(BN17:BT17) -> 9 | BV17: 9 | BW17: 9 | BX17: 9 | BY17: =(AH17*$BY$1)+(BM17*$BY$2)+(BU17*$BY$3)+(BV17*$BY$4)+(BW17*$BY$5)+(BX17*$BY$6) -> 9
A18: 8 | B18: =DATOS!C18 -> GARCIA PINEDA IKER ALEJANDRO | D18: 10 | E18: 10 | F18: 9 | G18: 9 | H18: 8 | I18: 7 | J18: 8 | K18: 8 | L18: 8 | M18: 9 | N18: 9 | O18: 9 | P18: 7 | Q18: 9 | R18: 9 | S18: 8 | T18: 8 | U18: 9 | V18: 7 | W18: 8 | AH18: =AVERAGE(D18:AG18) -> 8.45 | AI18: 10 | BM18: =AVERAGE(AI18:BL18) -> 10 | BN18: 7 | BO18: 8 | BP18: 9 | BU18: =AVERAGE(BN18:BT18) -> 8 | BV18: 9 | BW18: 9 | BX18: 9.5 | BY18: =(AH18*$BY$1)+(BM18*$BY$2)+(BU18*$BY$3)+(BV18*$BY$4)+(BW18*$BY$5)+(BX18*$BY$6) -> 8.99
A19: 9 | B19: =DATOS!C19 -> GONZÁLEZ HERNÁNDEZ LUIS Á_x0081_NGEL | D19: 10 | E19: 10 | F19: 9 | G19: 8 | H19: 8 | I19: 8 | J19: 7 | K19: 7 | L19: 7 | M19: 7 | N19: 7 | O19: 8 | P19: 9 | Q19: 10 | R19: 9 | S19: 9 | T19: 10 | U19: 10 | V19: 9 | W19: 8 | AH19: =AVERAGE(D19:AG19) -> 8.5 | AI19: 7 | BM19: =AVERAGE(AI19:BL19) -> 7 | BN19: 7 | BO19: 8 | BP19: 9 | BU19: =AVERAGE(BN19:BT19) -> 8 | BV19: 9 | BW19: 9 | BX19: 9 | BY19: =(AH19*$BY$1)+(BM19*$BY$2)+(BU19*$BY$3)+(BV19*$BY$4)+(BW19*$BY$5)+(BX19*$BY$6) -> 8.3
A20: 10 | B20: =DATOS!C20 -> GRIMALDO PUENTE SAMANTHA SARAHI | D20: 10 | E20: 10 | F20: 10 | G20: 10 | H20: 10 | I20: 10 | J20: 10 | K20: 9 | L20: 9 | M20: 9 | N20: 9 | O20: 10 | P20: 9 | Q20: 9 | R20: 9 | S20: 10 | T20: 10 | U20: 10 | V20: 10 | W20: 10 | AH20: =AVERAGE(D20:AG20) -> 9.65 | AI20: 9 | BM20: =AVERAGE(AI20:BL20) -> 9 | BN20: 8 | BO20: 9 | BP20: 10 | BU20: =AVERAGE(BN20:BT20) -> 9 | BV20: 10 | BW20: 10 | BX20: 9.5 | BY20: =(AH20*$BY$1)+(BM20*$BY$2)+(BU20*$BY$3)+(BV20*$BY$4)+(BW20*$BY$5)+(BX20*$BY$6) -> 9.43
A21: 11 | B21: =DATOS!C21 -> GUERRERO RODRIGUEZ KEYSHA CECILIA | D21: 8 | E21: 7 | F21: 7 | G21: 6 | H21: 6 | I21: 6 | J21: 6 | K21: 6 | L21: 6 | M21: 8 | N21: 7 | O21: 8 | P21: 7 | Q21: 7 | R21: 7 | S21: 7 | T21: 7 | U21: 7 | V21: 8 | W21: 8 | AH21: =AVERAGE(D21:AG21) -> 6.95 | AI21: 6 | BM21: =AVERAGE(AI21:BL21) -> 6 | BN21: 6 | BO21: 7 | BP21: 8 | BU21: =AVERAGE(BN21:BT21) -> 7 | BV21: 6 | BW21: 6 | BX21: 3 | BY21: =(AH21*$BY$1)+(BM21*$BY$2)+(BU21*$BY$3)+(BV21*$BY$4)+(BW21*$BY$5)+(BX21*$BY$6) -> 5.79
A22: 12 | B22: =DATOS!C22 -> HERNANDEZ CRUZ VIRIDIANA MARIE | D22: 10 | E22: 10 | F22: 9 | G22: 9 | H22: 9 | I22: 9 | J22: 8 | K22: 9 | L22: 9 | M22: 9 | N22: 9 | O22: 9 | P22: 10 | Q22: 10 | R22: 10 | S22: 10 | T22: 10 | U22: 10 | V22: 10 | W22: 10 | AH22: =AVERAGE(D22:AG22) -> 9.45 | AI22: 10 | BM22: =AVERAGE(AI22:BL22) -> 10 | BN22: 8 | BO22: 9 | BP22: 10 | BU22: =AVERAGE(BN22:BT22) -> 9 | BV22: 9 | BW22: 9 | BX22: 9 | BY22: =(AH22*$BY$1)+(BM22*$BY$2)+(BU22*$BY$3)+(BV22*$BY$4)+(BW22*$BY$5)+(BX22*$BY$6) -> 9.29
... A27: 17 | B27: =DATOS!C27 -> MEZA TURRUBIATES BRITANY YAHIRALIZ | D27: 10 | E27: 10 | F27: 10 | G27: 10 | H27: 9 | I27: 9 | J27: 9 | K27: 9 | L27: 10 | M27: 10 | N27: 10 | O27: 10 | P27: 10 | Q27: 9 | R27: 10 | S27: 9 | T27: 9 | U27: 9 | V27: 10 | W27: 10 | AH27: =AVERAGE(D27:AG27) -> 9.6 | AI27: 8 | BM27: =AVERAGE(AI27:BL27) -> 8 | BN27: 8 | BO27: 9 | BP27: 10 | BU27: =AVERAGE(BN27:BT27) -> 9 | BV27: 10 | BW27: 10 | BX27: 8.5 | BY27: =(AH27*$BY$1)+(BM27*$BY$2)+(BU27*$BY$3)+(BV27*$BY$4)+(BW27*$BY$5)+(BX27*$BY$6) -> 9.02
A28: 18 | B28: =DATOS!C28 -> PEÑA MEDELLÍN CORAL ANJURY | D28: 10 | E28: 10 | F28: 7 | G28: 7 | H28: 6 | I28: 6 | J28: 6 | K28: 6 | L28: 7 | AH28: =AVERAGE(D28:AG28) -> 7.2222222 | BM28: =AVERAGE(AI28:BL28) -> #DIV/0! | BN28: 9 | BO28: 10 | BP28: 10 | BV28: 7 | BW28: 7 | BX28: 3.5 | BY28: 6
A29: 19 | B29: =DATOS!C29 -> RAMIREZ GUEIXPAL VANIA GUADALUPE | D29: 10 | E29: 10 | F29: 10 | G29: 10 | H29: 10 | I29: 10 | J29: 10 | K29: 10 | L29: 10 | M29: 10 | N29: 10 | O29: 10 | P29: 10 | Q29: 10 | R29: 10 | S29: 10 | T29: 10 | U29: 10 | V29: 10 | W29: 10 | AH29: =AVERAGE(D29:AG29) -> 10 | AI29: 10 | BM29: =AVERAGE(AI29:BL29) -> 10 | BN29: 10 | BO29: 10 | BP29: 9 | BU29: =AVERAGE(BN29:BT29) -> 9.6666667 | BV29: 10 | BW29: 10 | BX29: 9.5 | BY29: =(AH29*$BY$1)+(BM29*$BY$2)+(BU29*$BY$3)+(BV29*$BY$4)+(BW29*$BY$5)+(BX29*$BY$6) -> 9.8333333
A30: 20 | B30: =DATOS!C30 -> RAMIREZ MARTINEZ EDWIN EMMANUEL | D30: 6 | E30: 6 | F30: 6 | G30: 6 | H30: 6 | I30: 6 | J30: 6 | K30: 6 | L30: 6 | M30: 6 | N30: 6 | O30: 6 | P30: 6 | Q30: 6 | R30: 6 | S30: 6 | T30: 6 | U30: 6 | V30: 6 | W30: 6 | AH30: =AVERAGE(D30:AG30) -> 6 | AI30: 8 | BM30: =AVERAGE(AI30:BL30) -> 8 | BN30: 6 | BO30: 7 | BP30: 8 | BU30: =AVERAGE(BN30:BT30) -> 7 | BV30: 7 | BW30: 7 | BX30: 8 | BY30: =(AH30*$BY$1)+(BM30*$BY$2)+(BU30*$BY$3)+(BV30*$BY$4)+(BW30*$BY$5)+(BX30*$BY$6) -> 7.2
A31: 21 | B31: =DATOS!C31 -> RANGEL GARCÍA DANIEL TIMOTEO | D31: 9 | E31: 8 | F31: 8 | G31: 7 | H31: 7 | I31: 7 | J31: 9 | K31: 8 | L31: 8 | M31: 9 | N31: 8 | O31: 8 | P31: 8 | Q31: 8 | R31: 8 | S31: 8 | T31: 8 | U31: 8 | V31: 8 | W31: 8 | AH31: =AVERAGE(D31:AG31) -> 8 | AI31: 7 | BM31: =AVERAGE(AI31:BL31) -> 7 | BN31: 4 | BO31: 5 | BP31: 6 | BU31: =AVERAGE(BN31:BT31) -> 5 | BV31: 8 | BW31: 8 | BX31: 9 | BY31: =(AH31*$BY$1)+(BM31*$BY$2)+(BU31*$BY$3)+(BV31*$BY$4)+(BW31*$BY$5)+(BX31*$BY$6) -> 7.4
A32: 22 | B32: =DATOS!C32 -> ROCHA RAMÍREZ CRISTIAN GUADALUPE | D32: 6 | E32: 5 | F32: 6 | G32: 6 | H32: 6 | I32: 5 | J32: 5 | K32: 5 | L32: 5 | M32: 5 | N32: 6 | O32: 6 | P32: 6 | Q32: 5 | R32: 6 | S32: 5 | T32: 6 | U32: 6 | V32: 5 | W32: 5 | AH32: =AVERAGE(D32:AG32) -> 5.5 | AI32: 5 | BM32: =AVERAGE(AI32:BL32) -> 5 | BN32: 6 | BO32: 7 | BP32: 8 | BU32: =AVERAGE(BN32:BT32) -> 7 | BV32: 5 | BW32: 5 | BX32: 8 | BY32: =(AH32*$BY$1)+(BM32*$BY$2)+(BU32*$BY$3)+(BV32*$BY$4)+(BW32*$BY$5)+(BX32*$BY$6) -> 6.1
A33: 23 | B33: =DATOS!C33 -> RODULFO ARGÜELLO ISAÍAS TADEO | D33: 8 | E33: 8 | F33: 9 | G33: 7 | H33: 6 | I33: 6 | J33: 6 | K33: 6 | L33: 7 | M33: 6 | N33: 6 | O33: 6 | P33: 6 | Q33: 7 | R33: 7 | S33: 7 | T33: 8 | U33: 8 | V33: 8 | W33: 8 | AH33: =AVERAGE(D33:AG33) -> 7 | AI33: 7 | BM33: =AVERAGE(AI33:BL33) -> 7 | BN33: 9 | BO33: 8 | BP33: 8 | BU33: =AVERAGE(BN33:BT33) -> 8.3333333 | BV33: 7 | BW33: 7 | BX33: 7.5 | BY33: =(AH33*$BY$1)+(BM33*$BY$2)+(BU33*$BY$3)+(BV33*$BY$4)+(BW33*$BY$5)+(BX33*$BY$6) -> 7.3666667
A34: 24 | B34: =DATOS!C34 -> RUBIO HERNÁNDEZ EVELIN | D34: 10 | E34: 10 | F34: 10 | G34: 10 | H34: 10 | I34: 10 | J34: 10 | K34: 10 | L34: 9 | M34: 10 | N34: 10 | O34: 9 | P34: 9 | Q34: 9 | R34: 10 | S34: 10 | T34: 10 | U34: 10 | V34: 9 | W34: 10 | AH34: =AVERAGE(D34:AG34) -> 9.75 | AI34: 10 | BM34: =AVERAGE(AI34:BL34) -> 10 | BN34: 8 | BO34: 9 | BP34: 10 | BU34: =AVERAGE(BN34:BT34) -> 9 | BV34: 10 | BW34: 10 | BX34: 10 | BY34: =(AH34*$BY$1)+(BM34*$BY$2)+(BU34*$BY$3)+(BV34*$BY$4)+(BW34*$BY$5)+(BX34*$BY$6) -> 9.75
A35: 25 | B35: =DATOS!C35 -> SALAZAR GOMEZ OSVALDO DAMIAN | D35: 9 | E35: 8 | F35: 8 | G35: 9 | H35: 7 | I35: 9 | J35: 8 | K35: 6 | L35: 6 | M35: 8 | N35: 8 | O35: 7 | P35: 7 | Q35: 7 | R35: 9 | S35: 6 | T35: 7 | U35: 7 | V35: 7 | W35: 7 | AH35: =AVERAGE(D35:AG35) -> 7.5 | AI35: 10 | BM35: =AVERAGE(AI35:BL35) -> 10 | BN35: 6 | BO35: 7 | BP35: 8 | BU35: =AVERAGE(BN35:BT35) -> 7 | BV35: 9 | BW35: 9 | BX35: 8.5 | BY35: =(AH35*$BY$1)+(BM35*$BY$2)+(BU35*$BY$3)+(BV35*$BY$4)+(BW35*$BY$5)+(BX35*$BY$6) -> 8.4
A36: 26 | B36: =DATOS!C36 -> SANTIAGO DEL ANGEL JESUS ANTONIO | D36: 10 | E36: 10 | F36: 10 | G36: 9 | H36: 8 | I36: 10 | J36: 9 | K36: 9 | L36: 9 | M36: 9 | N36: 10 | O36: 9 | P36: 9 | Q36: 10 | R36: 10 | S36: 10 | T36: 10 | U36: 9 | V36: 10 | W36: 9 | AH36: =AVERAGE(D36:AG36) -> 9.45 | AI36: 7 | BM36: =AVERAGE(AI36:BL36) -> 7 | BN36: 6 | BO36: 7 | BP36: 8 | BU36: =AVERAGE(BN36:BT36) -> 7 | BV36: 8 | BW36: 8 | BX36: 10 | BY36: =(AH36*$BY$1)+(BM36*$BY$2)+(BU36*$BY$3)+(BV36*$BY$4)+(BW36*$BY$5)+(BX36*$BY$6) -> 8.29
A37: 27 | B37: =DATOS!C37 -> SILVA GONZALEZ LEONARDO SAID | D37: 7 | E37: 7 | F37: 7 | G37: 7 | H37: 6 | I37: 6 | J37: 6 | K37: 6 | L37: 6 | M37: 6 | N37: 7 | O37: 7 | P37: 7 | Q37: 7 | R37: 7 | S37: 6 | T37: 6 | U37: 6 | V37: 6 | W37: 6 | AH37: =AVERAGE(D37:AG37) -> 6.45 | AI37: 7 | BM37: =AVERAGE(AI37:BL37) -> 7 | BN37: 6 | BO37: 7 | BP37: 8 | BU37: =AVERAGE(BN37:BT37) -> 7 | BV37: 7 | BW37: 7 | BX37: 9 | BY37: =(AH37*$BY$1)+(BM37*$BY$2)+(BU37*$BY$3)+(BV37*$BY$4)+(BW37*$BY$5)+(BX37*$BY$6) -> 7.29
A38: 28 | B38: =DATOS!C38 -> TOBIAS LOZANO ESTEFANY LIZBETH | D38: 9 | E38: 8 | F38: 8 | G38: 6 | H38: 7 | I38: 7 | J38: 7 | K38: 7 | L38: 7 | M38: 7 | N38: 6 | O38: 7 | P38: 7 | Q38: 6 | R38: 7 | S38: 6 | T38: 7 | U38: 7 | V38: 7 | W38: 7 | AH38: =AVERAGE(D38:AG38) -> 7 | AI38: 7 | BM38: =AVERAGE(AI38:BL38) -> 7 | BN38: 5 | BO38: 6 | BP38: 7 | BU38: =AVERAGE(BN38:BT38) -> 6 | BV38: 8 | BW38: 8 | BX38: 9.5 | BY38: =(AH38*$BY$1)+(BM38*$BY$2)+(BU38*$BY$3)+(BV38*$BY$4)+(BW38*$BY$5)+(BX38*$BY$6) -> 7.5
A39: 29 | B39: =DATOS!C39 -> TORRES MEDINA JOSHLEY ALEJANDRO | D39: 6 | E39: 6 | F39: 6 | G39: 6 | H39: 6 | I39: 6 | J39: 6 | K39: 6 | L39: 6 | M39: 6 | N39: 6 | O39: 6 | P39: 6 | Q39: 6 | R39: 6 | S39: 6 | T39: 6 | U39: 6 | V39: 6 | W39: 6 | AH39: =AVERAGE(D39:AG39) -> 6 | AI39: 6 | BM39: =AVERAGE(AI39:BL39) -> 6 | BN39: 7 | BO39: 7 | BP39: 7 | BU39: =AVERAGE(BN39:BT39) -> 7 | BV39: 5 | BW39: 5 | BX39: 7.5 | BY39: =(AH39*$BY$1)+(BM39*$BY$2)+(BU39*$BY$3)+(BV39*$BY$4)+(BW39*$BY$5)+(BX39*$BY$6) -> 6.3
A40: 30 | B40: =DATOS!C40 -> RAMÍREZ CORREA ALISSON | O40: 10 | P40: 10 | Q40: 9 | R40: 9 | S40: 9 | T40: 10 | U40: 10 | V40: 10 | W40: 10 | AH40: =AVERAGE(D40:AG40) -> 9.6666667 | AI40: 10 | BM40: =AVERAGE(AI40:BL40) -> 10 | BO40: 9 | BP40: 9 | BU40: =AVERAGE(BN40:BT40) -> 9 | BV40: 10 | BW40: 10 | BX40: 10 | BY40: =(AH40*$BY$1)+(BM40*$BY$2)+(BU40*$BY$3)+(BV40*$BY$4)+(BW40*$BY$5)+(BX40*$BY$6) -> 9.7333333
A41: 31 | B41: =DATOS!C41
A42: 32 | B42: =DATOS!C42
A43: 33 | B43: =DATOS!C43
A44: 34 | B44: =DATOS!C44
A45: 35 | B45: =DATOS!C45
...

Sheet 3er Trimestre
A1: =DATOS!D3 -> EST 128 | BR1: ACTIVIDADES | BT1: 0.2
A2: DOCENTE: | B2: =DATOS!D4 -> Omar Mata | BR2: TAREAS | BT2: 0.2
A3: GRADO: | B3: =DATOS!D5 -> 3 | C3: =DATOS!D6 -> E | BI3: PROYECTOS | BR3: PROYECTOS | BT3: 0.2
A4: Materia | B4: TECNOLOGÍA | BI4: Infografia Ciberseguridad | BJ4: Exposiciones | BK4: Día de las Madres | BR4: PARTICIPACIÓN | BT4: 0.1
BR5: CONDUCTA | BT5: 0.1
BR6: EVALUACIÓN | BT6: 0.2
BR7: PORCENTAJE TOTAL | BT7: =SUM(BT1:BT6) -> 1
D9: ACTIVIDADES | AD9: TAREAS | BQ9: PARTICIPACIÓN | BR9: CONDUCTA | BS9: EVALUACIÓN (Examen) | BT9: CALIF FINAL
A10: N° | B10: NOMBRE | D10: 1 | E10: 2 | F10: 3 | G10: 4 | H10: 5 | I10: 6 | J10: 7 | K10: 8 | L10: 9 | M10: 10 | N10: 11 | O10: 12 | P10: 13 | Q10: 14 | R10: 15 | S10: 16 | T10: 17 | U10: 18 | V10: 19 | W10: 20 | X10: 21 | Y10: 22 | Z10: 23 | AA10: 24 | AB10: 25 | AC10: PROMEDIO ACTIVIDADES | AD10: 1 | AE10: 2 | AF10: 3 | AG10: 4 | AH10: 5 | AI10: 6 | AJ10: 7 | AK10: 8 | AL10: 9 | AM10: 10 | AN10: 11 | AO10: 12 | AP10: 13 | AQ10: 14 | AR10: 15 | AS10: 16 | AT10: 17 | AU10: 18 | AV10: 19 | AW10: 20 | AX10: 21 | AY10: 22 | AZ10: 23 | BA10: 24 | BB10: 25 | BC10: 26 | BD10: 27 | BE10: 28 | BF10: 29 | BG10: 30 | BH10: PROMEDIO TAREAS | BI10: 1 | BJ10: 2 | BK10: 3 | BL10: 2 | BM10: 3 | BN10: 4 | BO10: 5 | BP10: PROMEDIO PROYECTOS
A11: 1 | B11: =DATOS!C11 -> ARMENDARIZ CUELLAR MIA ISABELLA | D11: 10 | E11: 9.8 | F11: 10 | G11: 9 | H11: 10 | I11: 9.6 | J11: 9.8 | K11: 10 | L11: 9.4 | M11: 10 | N11: 10 | O11: 9.2 | P11: 9.8 | Q11: 10 | R11: 10 | S11: 9.4 | T11: 10 | U11: 9.2 | V11: 8.8 | W11: 9.4 | X11: 9.2 | Y11: 10 | Z11: 9.8 | AA11: 9.6 | AB11: 10 | AC11: =ROUND(AVERAGE(D11:AB11),0) -> 10 | AD11: 9 | BH11: =AVERAGE(AD11:BG11) -> 9 | BI11: 10 | BJ11: 10 | BK11: 10 | BP11: =AVERAGE(BI11:BO11) -> 10 | BQ11: 10 | BR11: 10 | BS11: 8.5 | BT11: =ROUND((AC11*$BT$1)+(BH11*$BT$2)+(BP11*$BT$3)+(BQ11*$BT$4)+(BR11*$BT$5)+(BS11*$BT$6),0) -> 10
A12: 2 | B12: =DATOS!C12 -> BLANCO SALGADO LLUVIA CRISTAL | D12: 10 | E12: 10 | F12: 10 | G12: 9.6 | H12: 10 | I12: 10 | J12: 10 | K12: 9.8 | L12: 9 | M12: 8.8 | N12: 9 | O12: 9.4 | P12: 9 | Q12: 10 | R12: 10 | S12: 9 | T12: 9 | U12: 9.6 | V12: 10 | W12: 9 | X12: 10 | Y12: 9.6 | Z12: 10 | AA12: 9.6 | AB12: 10 | AC12: =ROUND(AVERAGE(D12:AB12),0) -> 10 | AD12: 8 | BH12: =AVERAGE(AD12:BG12) -> 8 | BI12: 10 | BJ12: 10 | BK12: 10 | BP12: =AVERAGE(BI12:BO12) -> 10 | BQ12: 10 | BR12: 10 | BS12: 9.5 | BT12: =ROUND((AC12*$BT$1)+(BH12*$BT$2)+(BP12*$BT$3)+(BQ12*$BT$4)+(BR12*$BT$5)+(BS12*$BT$6),0) -> 10
A13: 3 | B13: =DATOS!C13 -> CANTU AGUILAR ASHLEY DAYANA | D13: 8.8 | E13: 6 | F13: 7.9 | G13: 5.1 | H13: 5.2 | I13: 5.6 | J13: 8.1 | K13: 7.1 | L13: 5.3 | M13: 6.3 | N13: 6.4 | O13: 7.6 | P13: 6.9 | Q13: 8.4 | R13: 9.3 | S13: 8.5 | T13: 6.1 | U13: 8 | V13: 6.2 | W13: 7.2 | X13: 7 | Y13: 7.4 | Z13: 5.8 | AA13: 6.5 | AB13: 7 | AC13: =ROUND(AVERAGE(D13:AB13),0) -> 7 | AD13: 7 | BH13: =AVERAGE(AD13:BG13) -> 7 | BI13: 8 | BJ13: 9 | BK13: 10 | BP13: =AVERAGE(BI13:BO13) -> 9 | BQ13: 8 | BR13: 7 | BS13: 6.5 | BT13: =ROUND((AC13*$BT$1)+(BH13*$BT$2)+(BP13*$BT$3)+(BQ13*$BT$4)+(BR13*$BT$5)+(BS13*$BT$6),0) -> 7
A14: 4 | B14: =DATOS!C14 -> CRUZ HERNÁNDEZ ALAN ABDIEL | D14: 8 | E14: 9.8 | F14: 7.1 | G14: 7 | H14: 6.6 | I14: 8.8 | J14: 6.7 | K14: 8.3 | L14: 6.9 | M14: 10 | N14: 7.6 | O14: 7.7 | P14: 7.5 | Q14: 9.6 | R14: 7.9 | S14: 7.3 | T14: 9 | U14: 9.9 | V14: 9.4 | W14: 9.6 | X14: 8.6 | Y14: 8.9 | Z14: 9.2 | AA14: 9.3 | AB14: 8 | AC14: =ROUND(AVERAGE(D14:AB14),0) -> 8 | AD14: 8 | BH14: =AVERAGE(AD14:BG14) -> 8 | BI14: 8 | BJ14: 9 | BK14: 10 | BP14: =AVERAGE(BI14:BO14) -> 9 | BQ14: 8 | BR14: 8 | BS14: 8.5 | BT14: =ROUND((AC14*$BT$1)+(BH14*$BT$2)+(BP14*$BT$3)+(BQ14*$BT$4)+(BR14*$BT$5)+(BS14*$BT$6),0) -> 8
A15: 5 | B15: =DATOS!C15 -> DE LEON SALINAS VANESA MONSERRAT | D15: 8 | E15: 8.9 | F15: 7.4 | G15: 8.1 | H15: 9 | I15: 9.8 | J15: 6.9 | K15: 9.1 | L15: 9.6 | M15: 10 | N15: 7.7 | O15: 7.9 | P15: 9.3 | Q15: 9.9 | R15: 7.2 | S15: 7 | T15: 9.7 | U15: 7.1 | V15: 7.3 | W15: 8.7 | X15: 8.8 | Y15: 7.5 | Z15: 9.4 | AA15: 9.9 | AB15: 8 | AC15: =ROUND(AVERAGE(D15:AB15),0) -> 8 | AD15: 10 | BH15: =AVERAGE(AD15:BG15) -> 10 | BI15: 8 | BJ15: 9 | BK15: 10 | BP15: =AVERAGE(BI15:BO15) -> 9 | BQ15: 7 | BR15: 8 | BS15: 7 | BT15: =ROUND((AC15*$BT$1)+(BH15*$BT$2)+(BP15*$BT$3)+(BQ15*$BT$4)+(BR15*$BT$5)+(BS15*$BT$6),0) -> 8
A16: 6 | B16: =DATOS!C16 -> DORIA GUERRA DAILY ALESSANDRA | D16: 9.4 | E16: 8.8 | F16: 10 | G16: 9.8 | H16: 10 | I16: 10 | J16: 10 | K16: 9 | L16: 10 | M16: 10 | N16: 10 | O16: 10 | P16: 9 | Q16: 10 | R16: 10 | S16: 8.8 | T16: 9 | U16: 9.4 | V16: 10 | W16: 9.6 | X16: 10 | Y16: 10 | Z16: 10 | AA16: 10 | AB16: 10 | AC16: =ROUND(AVERAGE(D16:AB16),0) -> 10 | AD16: 10 | BH16: =AVERAGE(AD16:BG16) -> 10 | BI16: 10 | BJ16: 10 | BK16: 10 | BP16: =AVERAGE(BI16:BO16) -> 10 | BQ16: 10 | BR16: 10 | BS16: 9 | BT16: =ROUND((AC16*$BT$1)+(BH16*$BT$2)+(BP16*$BT$3)+(BQ16*$BT$4)+(BR16*$BT$5)+(BS16*$BT$6),0) -> 10
A17: 7 | B17: =DATOS!C17 -> ELIZONDO ROMERO MONTSERRAT GUADALUPE | D17: 9.6 | E17: 7.8 | F17: 8.6 | G17: 8.8 | H17: 9.6 | I17: 9.4 | J17: 8.8 | K17: 8.8 | L17: 8.2 | M17: 8.4 | N17: 9.8 | O17: 9.2 | P17: 8 | Q17: 7.8 | R17: 10 | S17: 10 | T17: 7.8 | U17: 8.8 | V17: 8.6 | W17: 7.8 | X17: 9.6 | Y17: 9.6 | Z17: 9 | AA17: 8 | AB17: 9 | AC17: =ROUND(AVERAGE(D17:AB17),0) -> 9 | AD17: 9 | BH17: =AVERAGE(AD17:BG17) -> 9 | BI17: 8 | BJ17: 9 | BK17: 10 | BP17: =AVERAGE(BI17:BO17) -> 9 | BQ17: 9 | BR17: 9 | BS17: 9.5 | BT17: =ROUND((AC17*$BT$1)+(BH17*$BT$2)+(BP17*$BT$3)+(BQ17*$BT$4)+(BR17*$BT$5)+(BS17*$BT$6),0) -> 9
A18: 8 | B18: =DATOS!C18 -> GARCIA PINEDA IKER ALEJANDRO | D18: 8.2 | E18: 7.2 | F18: 8.1 | G18: 9.8 | H18: 6.8 | I18: 8.4 | J18: 8.5 | K18: 7 | L18: 9.9 | M18: 9.7 | N18: 9.6 | O18: 8 | P18: 9.5 | Q18: 7.8 | R18: 6.9 | S18: 9.3 | T18: 7.3 | U18: 8.9 | V18: 10 | W18: 10 | X18: 6.5 | Y18: 9.4 | Z18: 8.6 | AA18: 9.2 | AB18: 9 | AC18: =ROUND(AVERAGE(D18:AB18),0) -> 9 | AD18: 10 | BH18: =AVERAGE(AD18:BG18) -> 10 | BI18: 7 | BJ18: 8 | BK18: 9 | BP18: =AVERAGE(BI18:BO18) -> 8 | BQ18: 9 | BR18: 9 | BS18: 9.5 | BT18: =ROUND((AC18*$BT$1)+(BH18*$BT$2)+(BP18*$BT$3)+(BQ18*$BT$4)+(BR18*$BT$5)+(BS18*$BT$6),0) -> 9
A19: 9 | B19: =DATOS!C19 -> GONZÁLEZ HERNÁNDEZ LUIS Á_x0081_NGEL | D19: 10 | E19: 7.8 | F19: 9.7 | G19: 7.6 | H19: 9 | I19: 6.8 | J19: 9.2 | K19: 8.2 | L19: 6.9 | M19: 8.3 | N19: 8.9 | O19: 8.5 | P19: 8.6 | Q19: 6.5 | R19: 9.9 | S19: 7.4 | T19: 9.4 | U19: 8 | V19: 9.8 | W19: 9.1 | X19: 9.3 | Y19: 7.7 | Z19: 8.8 | AA19: 10 | AB19: 8 | AC19: =ROUND(AVERAGE(D19:AB19),0) -> 9 | AD19: 7 | BH19: =AVERAGE(AD19:BG19) -> 7 | BI19: 8 | BJ19: 7 | BK19: 9 | BP19: =AVERAGE(BI19:BO19) -> 8 | BQ19: 9 | BR19: 9 | BS19: 8.5 | BT19: =ROUND((AC19*$BT$1)+(BH19*$BT$2)+(BP19*$BT$3)+(BQ19*$BT$4)+(BR19*$BT$5)+(BS19*$BT$6),0) -> 8
A20: 10 | B20: =DATOS!C20 -> GRIMALDO PUENTE SAMANTHA SARAHI | D20: 10 | E20: 10 | F20: 8.3 | G20: 10 | H20: 9.1 | I20: 10 | J20: 8.9 | K20: 9.3 | L20: 10 | M20: 8.5 | N20: 10 | O20: 10 | P20: 9.3 | Q20: 10 | R20: 9.7 | S20: 10 | T20: 8.5 | U20: 8.5 | V20: 9.1 | W20: 10 | X20: 9.1 | Y20: 8.5 | Z20: 9.7 | AA20: 8.5 | AB20: 9 | AC20: =ROUND(AVERAGE(D20:AB20),0) -> 9 | AD20: 9 | BH20: =AVERAGE(AD20:BG20) -> 9 | BI20: 9 | BJ20: 8 | BK20: 10 | BP20: =AVERAGE(BI20:BO20) -> 9 | BQ20: 10 | BR20: 10 | BS20: 9.5 | BT20: =ROUND((AC20*$BT$1)+(BH20*$BT$2)+(BP20*$BT$3)+(BQ20*$BT$4)+(BR20*$BT$5)+(BS20*$BT$6),0) -> 9
A21: 11 | B21: =DATOS!C21 -> GUERRERO RODRIGUEZ KEYSHA CECILIA | D21: 7.2 | E21: 6.6 | F21: 7.6 | G21: 5.4 | H21: 6.8 | I21: 7.8 | J21: 6.2 | K21: 7.6 | L21: 7.8 | M21: 7.4 | N21: 7.2 | O21: 5.8 | P21: 5 | Q21: 6.8 | R21: 6.8 | S21: 7.6 | T21: 7.8 | U21: 7.8 | V21: 5.8 | W21: 7.8 | X21: 7.8 | Y21: 7.8 | Z21: 7.6 | AA21: 5.6 | AB21: 6 | AC21: =ROUND(AVERAGE(D21:AB21),0) -> 7 | AD21: 6 | BH21: =AVERAGE(AD21:BG21) -> 6 | BI21: 7 | BJ21: 6 | BK21: 8 | BP21: =AVERAGE(BI21:BO21) -> 7 | BQ21: 6 | BR21: 6 | BS21: 6.5 | BT21: =ROUND((AC21*$BT$1)+(BH21*$BT$2)+(BP21*$BT$3)+(BQ21*$BT$4)+(BR21*$BT$5)+(BS21*$BT$6),0) -> 7
A22: 12 | B22: =DATOS!C22 -> HERNANDEZ CRUZ VIRIDIANA MARIE | D22: 8.7 | E22: 8.7 | F22: 10 | G22: 9.3 | H22: 10 | I22: 10 | J22: 10 | K22: 9.9 | L22: 10 | M22: 8.7 | N22: 9.7 | O22: 9.7 | P22: 8.3 | Q22: 9.7 | R22: 10 | S22: 10 | T22: 9.7 | U22: 9.1 | V22: 10 | W22: 9.3 | X22: 8.9 | Y22: 10 | Z22: 9.9 | AA22: 8.5 | AB22: 10 | AC22: =ROUND(AVERAGE(D22:AB22),0) -> 10 | AD22: 10 | BH22: =AVERAGE(AD22:BG22) -> 10 | BI22: 9 | BJ22: 9 | BK22: 10 | BP22: =AVERAGE(BI22:BO22) -> 9.3333333 | BQ22: 9 | BR22: 9 | BS22: 8 | BT22: =ROUND((AC22*$BT$1)+(BH22*$BT$2)+(BP22*$BT$3)+(BQ22*$BT$4)+(BR22*$BT$5)+(BS22*$BT$6),0) -> 9
... A27: 17 | B27: =DATOS!C27 -> MEZA TURRUBIATES BRITANY YAHIRALIZ | D27: 10 | E27: 10 | F27: 10 | G27: 10 | H27: 9.4 | I27: 8.8 | J27: 9.4 | K27: 9 | L27: 9.6 | M27: 9.2 | N27: 9.2 | O27: 10 | P27: 9 | Q27: 8.4 | R27: 9.8 | S27: 9 | T27: 10 | U27: 9.8 | V27: 10 | W27: 10 | X27: 10 | Y27: 9.2 | Z27: 8.4 | AA27: 9.8 | AB27: 9 | AC27: =ROUND(AVERAGE(D27:AB27),0) -> 9 | AD27: 8 | BH27: =AVERAGE(AD27:BG27) -> 8 | BI27: 9 | BJ27: 8 | BK27: 10 | BP27: =AVERAGE(BI27:BO27) -> 9 | BQ27: 10 | BR27: 10 | BS27: 9 | BT27: =ROUND((AC27*$BT$1)+(BH27*$BT$2)+(BP27*$BT$3)+(BQ27*$BT$4)+(BR27*$BT$5)+(BS27*$BT$6),0) -> 9
A28: 18 | B28: =DATOS!C28 -> PEÑA MEDELLÍN CORAL ANJURY | D28: 6 | E28: 6 | F28: 6 | G28: 6 | H28: 6 | I28: 6 | J28: 6 | K28: 6 | L28: 6 | M28: 6 | AC28: =ROUND(AVERAGE(D28:AB28),0) -> 6 | BH28: =AVERAGE(AD28:BG28) -> #DIV/0! | BQ28: 7 | BR28: 7 | BS28: 5 | BT28: 6
A29: 19 | B29: =DATOS!C29 -> RAMIREZ GUEIXPAL VANIA GUADALUPE | D29: 8.8 | E29: 8.8 | F29: 9 | G29: 9.4 | H29: 10 | I29: 10 | J29: 10 | K29: 10 | L29: 10 | M29: 10 | N29: 9.6 | O29: 10 | P29: 10 | Q29: 10 | R29: 10 | S29: 10 | T29: 10 | U29: 10 | V29: 8.8 | W29: 9.2 | X29: 10 | Y29: 9.2 | Z29: 9 | AA29: 9.6 | AB29: 10 | AC29: =ROUND(AVERAGE(D29:AB29),0) -> 10 | AD29: 10 | BH29: =AVERAGE(AD29:BG29) -> 10 | BI29: 10 | BJ29: 10 | BK29: 10 | BP29: =AVERAGE(BI29:BO29) -> 10 | BQ29: 10 | BR29: 10 | BS29: 8.5 | BT29: =ROUND((AC29*$BT$1)+(BH29*$BT$2)+(BP29*$BT$3)+(BQ29*$BT$4)+(BR29*$BT$5)+(BS29*$BT$6),0) -> 10
A30: 20 | B30: =DATOS!C30 -> RAMIREZ MARTINEZ EDWIN EMMANUEL | D30: 6.4 | E30: 6 | F30: 6 | G30: 6 | H30: 5.6 | I30: 5.8 | J30: 6 | K30: 6 | L30: 5.4 | M30: 6.2 | N30: 5.4 | O30: 5.8 | P30: 5 | Q30: 6 | R30: 6.6 | S30: 5.8 | T30: 5.6 | U30: 5.6 | V30: 6 | W30: 5.6 | X30: 5.4 | Y30: 6.4 | Z30: 6 | AA30: 6.4 | AB30: 6 | AC30: =ROUND(AVERAGE(D30:AB30),0) -> 6 | AD30: 6 | BH30: =AVERAGE(AD30:BG30) -> 6 | BI30: 6 | BJ30: 6 | BK30: 6 | BP30: =AVERAGE(BI30:BO30) -> 6 | BQ30: 5 | BR30: 6 | BS30: 7.5 | BT30: =ROUND((AC30*$BT$1)+(BH30*$BT$2)+(BP30*$BT$3)+(BQ30*$BT$4)+(BR30*$BT$5)+(BS30*$BT$6),0) -> 6
A31: 21 | B31: =DATOS!C31 -> RANGEL GARCÍA DANIEL TIMOTEO | D31: 8.3 | E31: 7.9 | F31: 6.7 | G31: 6.6 | H31: 9.3 | I31: 8.7 | J31: 9.7 | K31: 9.1 | L31: 9.6 | M31: 6.5 | N31: 7.6 | O31: 9.2 | P31: 7.7 | Q31: 5.1 | R31: 9 | S31: 8.1 | T31: 8 | U31: 8.9 | V31: 8.8 | W31: 6.1 | X31: 7.2 | Y31: 8.6 | Z31: 7.8 | AA31: 9.5 | AB31: 8 | AC31: =ROUND(AVERAGE(D31:AB31),0) -> 8 | AD31: 7 | BH31: =AVERAGE(AD31:BG31) -> 7 | BI31: 6 | BJ31: 6 | BK31: 8 | BP31: =AVERAGE(BI31:BO31) -> 6.6666667 | BQ31: 6 | BR31: 7 | BS31: 9 | BT31: =ROUND((AC31*$BT$1)+(BH31*$BT$2)+(BP31*$BT$3)+(BQ31*$BT$4)+(BR31*$BT$5)+(BS31*$BT$6),0) -> 7
A32: 22 | B32: =DATOS!C32 -> ROCHA RAMÍREZ CRISTIAN GUADALUPE | D32: 5.5 | E32: 6.5 | F32: 5.9 | G32: 5 | H32: 5.1 | I32: 6.1 | J32: 5 | K32: 5 | L32: 5.3 | M32: 6.3 | N32: 5.3 | O32: 6.1 | P32: 5 | Q32: 5.3 | R32: 6.1 | S32: 5.7 | T32: 5 | U32: 5.3 | V32: 5 | W32: 5.3 | X32: 5.2 | Y32: 5.3 | Z32: 5 | AA32: 6.7 | AB32: 5 | AC32: =ROUND(AVERAGE(D32:AB32),0) -> 5 | AD32: 5 | BH32: =AVERAGE(AD32:BG32) -> 5 | BI32: 7 | BJ32: 6 | BK32: 8 | BP32: =AVERAGE(BI32:BO32) -> 7 | BQ32: 5 | BR32: 5 | BS32: 6 | BT32: =ROUND((AC32*$BT$1)+(BH32*$BT$2)+(BP32*$BT$3)+(BQ32*$BT$4)+(BR32*$BT$5)+(BS32*$BT$6),0) -> 6
A33: 23 | B33: =DATOS!C33 -> RODULFO ARGÜELLO ISAÍAS TADEO | D33: 5.6 | E33: 6.1 | F33: 8.1 | G33: 8.2 | H33: 5.8 | I33: 8 | J33: 8.4 | K33: 5.5 | L33: 6.7 | M33: 8.3 | N33: 8.6 | O33: 7.4 | P33: 5.2 | Q33: 6.8 | R33: 6.6 | S33: 5.3 | T33: 7.5 | U33: 6.4 | V33: 8.5 | W33: 8.7 | X33: 6.2 | Y33: 7.2 | Z33: 7.7 | AA33: 6.5 | AB33: 7 | AC33: =ROUND(AVERAGE(D33:AB33),0) -> 7 | AD33: 7 | BH33: =AVERAGE(AD33:BG33) -> 7 | BI33: 7 | BJ33: 7 | BK33: 7 | BP33: =AVERAGE(BI33:BO33) -> 7 | BQ33: 8 | BR33: 7 | BS33: 9 | BT33: =ROUND((AC33*$BT$1)+(BH33*$BT$2)+(BP33*$BT$3)+(BQ33*$BT$4)+(BR33*$BT$5)+(BS33*$BT$6),0) -> 8
A34: 24 | B34: =DATOS!C34 -> RUBIO HERNÁNDEZ EVELIN | D34: 10 | E34: 10 | F34: 9 | G34: 10 | H34: 10 | I34: 10 | J34: 10 | K34: 9.6 | L34: 9.8 | M34: 10 | N34: 10 | O34: 9.6 | P34: 10 | Q34: 9.4 | R34: 9.8 | S34: 10 | T34: 9.2 | U34: 10 | V34: 10 | W34: 10 | X34: 9 | Y34: 9.8 | Z34: 8.8 | AA34: 10 | AB34: 10 | AC34: =ROUND(AVERAGE(D34:AB34),0) -> 10 | AD34: 10 | BH34: =AVERAGE(AD34:BG34) -> 10 | BI34: 10 | BJ34: 10 | BK34: 10 | BP34: =AVERAGE(BI34:BO34) -> 10 | BQ34: 10 | BR34: 10 | BS34: 9.5 | BT34: =ROUND((AC34*$BT$1)+(BH34*$BT$2)+(BP34*$BT$3)+(BQ34*$BT$4)+(BR34*$BT$5)+(BS34*$BT$6),0) -> 10
A35: 25 | B35: =DATOS!C35 -> SALAZAR GOMEZ OSVALDO DAMIAN | D35: 8.4 | E35: 6.4 | F35: 6.6 | G35: 8.6 | H35: 8.8 | I35: 7 | J35: 7.3 | K35: 5.5 | L35: 6.1 | M35: 9.3 | N35: 8.3 | O35: 5.9 | P35: 9 | Q35: 7.9 | R35: 7.7 | S35: 6.5 | T35: 8.7 | U35: 9.6 | V35: 5.7 | W35: 7.2 | X35: 8.1 | Y35: 5.8 | Z35: 8.1 | AA35: 5.6 | AB35: 7 | AC35: =ROUND(AVERAGE(D35:AB35),0) -> 7 | AD35: 7 | BH35: =AVERAGE(AD35:BG35) -> 7 | BI35: 9 | BJ35: 9 | BK35: 9 | BP35: =AVERAGE(BI35:BO35) -> 9 | BQ35: 9 | BR35: 9 | BS35: 8 | BT35: =ROUND((AC35*$BT$1)+(BH35*$BT$2)+(BP35*$BT$3)+(BQ35*$BT$4)+(BR35*$BT$5)+(BS35*$BT$6),0) -> 8
A36: 26 | B36: =DATOS!C36 -> SANTIAGO DEL ANGEL JESUS ANTONIO | D36: 8.9 | E36: 9.7 | F36: 8.9 | G36: 10 | H36: 10 | I36: 9.3 | J36: 8.9 | K36: 8.7 | L36: 9.9 | M36: 8.9 | N36: 10 | O36: 10 | P36: 10 | Q36: 8.9 | R36: 9.7 | S36: 10 | T36: 9.9 | U36: 9.9 | V36: 8.5 | W36: 9.5 | X36: 9.1 | Y36: 9.7 | Z36: 10 | AA36: 8.7 | AB36: 10 | AC36: =ROUND(AVERAGE(D36:AB36),0) -> 9 | AD36: 7 | BH36: =AVERAGE(AD36:BG36) -> 7 | BI36: 7 | BJ36: 6 | BK36: 8 | BP36: =AVERAGE(BI36:BO36) -> 7 | BQ36: 8 | BR36: 8 | BS36: 10 | BT36: =ROUND((AC36*$BT$1)+(BH36*$BT$2)+(BP36*$BT$3)+(BQ36*$BT$4)+(BR36*$BT$5)+(BS36*$BT$6),0) -> 8
A37: 27 | B37: =DATOS!C37 -> SILVA GONZALEZ LEONARDO SAID | D37: 6 | E37: 7 | F37: 6.2 | G37: 6.4 | H37: 5.6 | I37: 6.6 | J37: 7 | K37: 6.6 | L37: 5.8 | M37: 5.8 | N37: 6.4 | O37: 6.6 | P37: 7.2 | Q37: 6.4 | R37: 6.2 | S37: 5.4 | T37: 5.8 | U37: 5.6 | V37: 5.6 | W37: 7.2 | X37: 6.2 | Y37: 7.4 | Z37: 5.8 | AA37: 10 | AB37: 7 | AC37: =ROUND(AVERAGE(D37:AB37),0) -> 6 | AD37: 7 | BH37: =AVERAGE(AD37:BG37) -> 7 | BI37: 7 | BJ37: 6 | BK37: 8 | BP37: =AVERAGE(BI37:BO37) -> 7 | BQ37: 9 | BR37: 7 | BS37: 9 | BT37: =ROUND((AC37*$BT$1)+(BH37*$BT$2)+(BP37*$BT$3)+(BQ37*$BT$4)+(BR37*$BT$5)+(BS37*$BT$6),0) -> 7
A38: 28 | B38: =DATOS!C38 -> TOBIAS LOZANO ESTEFANY LIZBETH | D38: 5.7 | E38: 6.5 | F38: 8.7 | G38: 5.2 | H38: 5.3 | I38: 8.9 | J38: 7.2 | K38: 6 | L38: 7.9 | M38: 7.5 | N38: 6.3 | O38: 5.5 | P38: 6.2 | Q38: 7.7 | R38: 5 | S38: 7.8 | T38: 8.5 | U38: 7.1 | V38: 7.3 | W38: 6.9 | X38: 6.1 | Y38: 8.8 | Z38: 6.4 | AA38: 8.4 | AB38: 7 | AC38: =ROUND(AVERAGE(D38:AB38),0) -> 7 | AD38: 7 | BH38: =AVERAGE(AD38:BG38) -> 7 | BI38: 7 | BJ38: 6 | BK38: 8 | BP38: =AVERAGE(BI38:BO38) -> 7 | BQ38: 8 | BR38: 9 | BS38: 8 | BT38: =ROUND((AC38*$BT$1)+(BH38*$BT$2)+(BP38*$BT$3)+(BQ38*$BT$4)+(BR38*$BT$5)+(BS38*$BT$6),0) -> 8
A39: 29 | B39: =DATOS!C39 -> TORRES MEDINA JOSHLEY ALEJANDRO | D39: 5.4 | E39: 6 | F39: 6.6 | G39: 6.2 | H39: 6 | I39: 5 | J39: 5 | K39: 6.8 | L39: 5 | M39: 5 | N39: 7.2 | O39: 6.6 | P39: 6.6 | Q39: 9.8 | R39: 6.4 | S39: 6 | T39: 5 | U39: 5.2 | V39: 6.8 | W39: 5 | X39: 6 | Y39: 5 | Z39: 5.4 | AA39: 5 | AB39: 6 | AC39: =ROUND(AVERAGE(D39:AB39),0) -> 6 | AD39: 6 | BH39: =AVERAGE(AD39:BG39) -> 6 | BI39: 6 | BJ39: 6 | BK39: 6 | BP39: =AVERAGE(BI39:BO39) -> 6 | BQ39: 5 | BR39: 5 | BS39: 7.5 | BT39: =ROUND((AC39*$BT$1)+(BH39*$BT$2)+(BP39*$BT$3)+(BQ39*$BT$4)+(BR39*$BT$5)+(BS39*$BT$6),0) -> 6
A40: 30 | B40: =DATOS!C40 -> RAMÍREZ CORREA ALISSON | D40: 10 | E40: 10 | F40: 10 | G40: 10 | H40: 10 | I40: 10 | J40: 10 | K40: 10 | L40: 10 | M40: 10 | N40: 10 | O40: 10 | P40: 10 | Q40: 9 | R40: 9 | S40: 9 | T40: 10 | U40: 10 | V40: 10 | AC40: =ROUND(AVERAGE(D40:AB40),0) -> 10 | AD40: 8 | BH40: =AVERAGE(AD40:BG40) -> 8 | BI40: 9 | BJ40: 9 | BK40: 9 | BP40: =AVERAGE(BI40:BO40) -> 9 | BQ40: 9 | BR40: 10 | BS40: 10 | BT40: =ROUND((AC40*$BT$1)+(BH40*$BT$2)+(BP40*$BT$3)+(BQ40*$BT$4)+(BR40*$BT$5)+(BS40*$BT$6),0) -> 9
A41: 31 | B41: =DATOS!C41
A42: 32 | B42: =DATOS!C42
A43: 33 | B43: =DATOS!C43
A44: 34 | B44: =DATOS!C44
A45: 35 | B45: =DATOS!C45
...

Sheet CONCENTRADO
A1: =DATOS!D3 -> EST 128
A2: DOCENTE: | B2: =DATOS!D4 -> Omar Mata
A3: GRADO: | B3: =DATOS!D5 -> 3 | C3: =DATOS!D6 -> E | E3: Tercer Trimestre | H3: ='3er Trimestre'!BT56 -> 8
E4: Segundo Trimestre | H4: ='2do Trimestre'!BY56 -> 8.0347778
E5: Primer Trimestre | H5: ='1er Trimestre'!BX56 -> 7.7264368
E6: PROMEDIO GENERAL GRUPAL | H6: =AVERAGE(H1:H5) -> 7.9204049
A8: N° | B8: NOMBRE | D8: 1er Trimestre | E8: 2do Trimestre | F8: 3er Trimestre
A9: 1 | B9: =DATOS!C11 -> ARMENDARIZ CUELLAR MIA ISABELLA | D9: ='1er Trimestre'!BX11 -> 8.9952381 | E9: ='2do Trimestre'!BY11 -> 9.6333333 | F9: ='3er Trimestre'!BT11 -> 10
A10: 2 | B10: =DATOS!C12 -> BLANCO SALGADO LLUVIA CRISTAL | D10: ='1er Trimestre'!BX12 -> 7.64 | E10: ='2do Trimestre'!BY12 -> 9.5333333 | F10: ='3er Trimestre'!BT12 -> 10
A11: 3 | B11: =DATOS!C13 -> CANTU AGUILAR ASHLEY DAYANA | D11: ='1er Trimestre'!BX13 -> 7.16 | E11: ='2do Trimestre'!BY13 -> 7.29 | F11: ='3er Trimestre'!BT13 -> 7
A12: 4 | B12: =DATOS!C14 -> CRUZ HERNÁNDEZ ALAN ABDIEL | D12: ='1er Trimestre'!BX14 -> 7.7104762 | E12: ='2do Trimestre'!BY14 -> 8.39 | F12: ='3er Trimestre'!BT14 -> 8
A13: 5 | B13: =DATOS!C15 -> DE LEON SALINAS VANESA MONSERRAT | D13: ='1er Trimestre'!BX15 -> 8.1190476 | E13: ='2do Trimestre'!BY15 -> 8.4 | F13: ='3er Trimestre'!BT15 -> 8
A14: 6 | B14: =DATOS!C16 -> DORIA GUERRA DAILY ALESSANDRA | D14: ='1er Trimestre'!BX16 -> 9.1647619 | E14: ='2do Trimestre'!BY16 -> 9.8333333 | F14: ='3er Trimestre'!BT16 -> 10
A15: 7 | B15: =DATOS!C17 -> ELIZONDO ROMERO MONTSERRAT GUADALUPE | D15: ='1er Trimestre'!BX17 -> 8.7904762 | E15: ='2do Trimestre'!BY17 -> 9 | F15: ='3er Trimestre'!BT17 -> 9
A16: 8 | B16: =DATOS!C18 -> GARCIA PINEDA IKER ALEJANDRO | D16: ='1er Trimestre'!BX18 -> 8.1314286 | E16: ='2do Trimestre'!BY18 -> 8.99 | F16: ='3er Trimestre'!BT18 -> 9
A17: 9 | B17: =DATOS!C19 -> GONZÁLEZ HERNÁNDEZ LUIS Á_x0081_NGEL | D17: ='1er Trimestre'!BX19 -> 7.64 | E17: ='2do Trimestre'!BY19 -> 8.3 | F17: ='3er Trimestre'!BT19 -> 8
A18: 10 | B18: =DATOS!C20 -> GRIMALDO PUENTE SAMANTHA SARAHI | D18: ='1er Trimestre'!BX20 -> 8.9952381 | E18: ='2do Trimestre'!BY20 -> 9.43 | F18: ='3er Trimestre'!BT20 -> 9
A19: 11 | B19: =DATOS!C21 -> GUERRERO RODRIGUEZ KEYSHA CECILIA | D19: ='1er Trimestre'!BX21 -> 5.647619 | E19: ='2do Trimestre'!BY21 -> 5.79 | F19: ='3er Trimestre'!BT21 -> 7
A20: 12 | B20: =DATOS!C22 -> HERNANDEZ CRUZ VIRIDIANA MARIE | D20: ='1er Trimestre'!BX22 -> 8.34 | E20: ='2do Trimestre'!BY22 -> 9.29 | F20: ='3er Trimestre'!BT22 -> 9
... A38: 30 | B38: =DATOS!C40 -> RAMÍREZ CORREA ALISSON | D38: ='1er Trimestre'!BX40 | E38: ='2do Trimestre'!BY40 -> 9.7333333 | F38: ='3er Trimestre'!BT40 -> 9
A39: 31 | B39: =DATOS!C41 | D39: ='1er Trimestre'!BX41 | F39: ='3er Trimestre'!BT41
A40: 32 | B40: =DATOS!C42 | D40: ='1er Trimestre'!BX42 | F40: ='3er Trimestre'!BT42
A41: 33 | B41: =DATOS!C43 | D41: ='1er Trimestre'!BX43 | F41: ='3er Trimestre'!BT43
A42: 34 | B42: =DATOS!C44 | D42: ='1er Trimestre'!BX44 | F42: ='3er Trimestre'!BT44
A43: 35 | B43: =DATOS!C45 | D43: ='1er Trimestre'!BX45 | F43: ='3er Trimestre'!BT45
A44: 36 | B44: =DATOS!C46 | D44: ='1er Trimestre'!BX46 | F44: ='3er Trimestre'!BT46
A45: 37 | B45: =DATOS!C47 | D45: ='1er Trimestre'!BX47 | F45: ='3er Trimestre'!BT47
A46: 38 | B46: =DATOS!C48 | D46: ='1er Trimestre'!BX48 | F46: ='3er Trimestre'!BT48
A47: 39 | B47: =DATOS!C49 | D47: ='1er Trimestre'!BX49 | F47: ='3er Trimestre'!BT49
A48: 40 | B48: =DATOS!C50 | D48: ='1er Trimestre'!BX50 | F48: ='3er Trimestre'!BT50
A49: 41 | B49: =DATOS!C51 | D49: ='1er Trimestre'!BX51 | F49: ='3er Trimestre'!BT51
A50: 42 | B50: =DATOS!C52 | D50: ='1er Trimestre'!BX52 | F50: ='3er Trimestre'!BT52
... A53: 45 | B53: =DATOS!C55 | D53: ='1er Trimestre'!BX55 | F53: ='3er Trimestre'!BT55
D54: =AVERAGEIF(D9:D53,"<>#¡DIV/0!") -> 7.7264368 | E54: =AVERAGEIF(E9:E53,"<>#¡DIV/0!") -> 8.0347778 | F54: =AVERAGEIF(F9:F53,"<>#¡DIV/0!") -> 8

Sheet RESULTADOS
B2: DATOS GENERALES
B3: NOMBRE DE LA ESCUELA: | C3: =DATOS!D3 -> EST 128
B4: NOMBRE DEL DOCENTE: | C4: =DATOS!D4 -> Omar Mata
B5: GRADO: | C5: =DATOS!D5 -> 3
B6: GRUPO: | C6: =DATOS!D6 -> E
B8: Trimestre | C8: PROMEDIO GRUPAL
B10: 3er Trimestre | C10: =CONCENTRADO!F54 -> 8
B11: 2do Trimestre | C11: =CONCENTRADO!E54 -> 8.0347778
B12: 1er Trimestre | C12: =CONCENTRADO!D54 -> 7.7264368
B13: PROMEDIO GRUPAL | C13: =AVERAGE(C9:C12) -> 7.9204049
